Workbook

Sheet Data
A1: Year | B1: Area | C1: Area Total | D1: Agriculture, forestry & fishing | E1: Mining, quarrying & utilities | F1: Manufacturing | G1: Construction | H1: Motor trades | I1: Wholesale | J1: Retail | K1: Transport & storage | L1: Accommodation & food services | M1: Information & communication | N1: Financial & insurance | O1: Property | P1: Professional, scientific & technical | Q1: Business administration & support services | R1: Public administration & defence | S1: Education | T1: Health | U1: Arts, entertainment, recreation & other services
A2: 2009 | B2: North Yorks County | C2: =SUM(D2:U2) -> 254000 | D2: 6000 | E2: 3500 | F2: 26000 | G2: 11000 | H2: 4500 | I2: 14000 | J2: 27000 | K2: 8000 | L2: 27000 | M2: 9000 | N2: 8000 | O2: 4000 | P2: 15000 | Q2: 13000 | R2: 11000 | S2: 22000 | T2: 33000 | U2: 12000
A3: 2009 | B3: South Yorks Met | C3: =SUM(D3:U3) -> 527500 | D3: 1000 | E3: 4500 | F3: 58000 | G3: 27000 | H3: 9000 | I3: 21000 | J3: 57000 | K3: 27000 | L3: 31000 | M3: 12000 | N3: 16000 | O3: 8000 | P3: 24000 | Q3: 38000 | R3: 31000 | S3: 58000 | T3: 85000 | U3: 20000
A4: 2009 | B4: West Yorks Met | C4: =SUM(D4:U4) -> 966750 | D4: 1750 | E4: 12000 | F4: 110000 | G4: 40000 | H4: 16000 | I4: 49000 | J4: 105000 | K4: 39000 | L4: 53000 | M4: 31000 | N4: 47000 | O4: 15000 | P4: 54000 | Q4: 77000 | R4: 58000 | S4: 98000 | T4: 125000 | U4: 36000
A5: 2009 | B5: Barnsley | C5: =SUM(D5:U5) -> 72125 | D5: 225 | E5: 400 | F5: 11000 | G5: 4000 | H5: 1250 | I5: 2500 | J5: 7000 | K5: 2500 | L5: 4500 | M5: 1250 | N5: 1750 | O5: 1250 | P5: 3000 | Q5: 3000 | R5: 5000 | S5: 8000 | T5: 13000 | U5: 2500
A6: 2009 | B6: Bradford | C6: =SUM(D6:U6) -> 194550 | D6: 300 | E6: 2250 | F6: 26000 | G6: 6000 | H6: 3000 | I6: 10000 | J6: 24000 | K6: 6000 | L6: 10000 | M6: 6000 | N6: 7000 | O6: 3000 | P6: 8000 | Q6: 12000 | R6: 12000 | S6: 23000 | T6: 29000 | U6: 7000
A7: 2009 | B7: Calderdale | C7: =SUM(D7:U7) -> 82875 | D7: 175 | E7: 450 | F7: 14000 | G7: 3500 | H7: 1250 | I7: 5000 | J7: 7000 | K7: 3000 | L7: 5000 | M7: 2500 | N7: 8000 | O7: 1500 | P7: 3000 | Q7: 5000 | R7: 4000 | S7: 8000 | T7: 9000 | U7: 2500
A8: 2009 | B8: Craven | C8: =SUM(D8:U8) -> 29150 | D8: 600 | E8: 200 | F8: 2250 | G8: 1500 | H8: 450 | I8: 1500 | J8: 3000 | K8: 700 | L8: 3000 | M8: 350 | N8: 3500 | O8: 500 | P8: 2000 | Q8: 3000 | R8: 300 | S8: 3000 | T8: 2500 | U8: 800
A9: 2009 | B9: Doncaster | C9: =SUM(D9:U9) -> 112350 | D9: 350 | E9: 1500 | F9: 10000 | G9: 7000 | H9: 2500 | I9: 4500 | J9: 14000 | K9: 9000 | L9: 7000 | M9: 1500 | N9: 2000 | O9: 1000 | P9: 3500 | Q9: 8000 | R9: 6000 | S9: 11000 | T9: 19000 | U9: 4500
A10: 2009 | B10: ER Yorks | C10: =SUM(D10:U10) -> 119150 | D10: 3000 | E10: 900 | F10: 14000 | G10: 5000 | H10: 2250 | I10: 5000 | J10: 12000 | K10: 5000 | L10: 9000 | M10: 2500 | N10: 2000 | O10: 1500 | P10: 5000 | Q10: 5000 | R10: 13000 | S10: 13000 | T10: 16000 | U10: 5000
A11: 2009 | B11: Hambleton | C11: =SUM(D11:U11) -> 37900 | D11: 1250 | E11: 350 | F11: 4000 | G11: 1750 | H11: 700 | I11: 2500 | J11: 4000 | K11: 1250 | L11: 3000 | M11: 600 | N11: 400 | O11: 600 | P11: 2250 | Q11: 1500 | R11: 4500 | S11: 2500 | T11: 5000 | U11: 1750
A12: 2009 | B12: Harrogate | C12: =SUM(D12:U12) -> 73100 | D12: 1250 | E12: 350 | F12: 4000 | G12: 2500 | H12: 1500 | I12: 4500 | J12: 8000 | K12: 2250 | L12: 7000 | M12: 7000 | N12: 3000 | O12: 1000 | P12: 5000 | Q12: 3000 | R12: 2250 | S12: 7000 | T12: 10000 | U12: 3500
A13: 2009 | B13: Hull | C13: =SUM(D13:U13) -> 116255 | D13: 5 | E13: 1250 | F13: 17000 | G13: 5000 | H13: 2000 | I13: 6000 | J13: 14000 | K13: 5000 | L13: 6000 | M13: 2250 | N13: 1500 | O13: 1250 | P13: 4000 | Q13: 11000 | R13: 8000 | S13: 11000 | T13: 17000 | U13: 4000
... A25: 2009 | B25: York | C25: =SUM(D25:U25) -> 104575 | D25: 225 | E25: 350 | F25: 4500 | G25: 4000 | H25: 1250 | I25: 2500 | J25: 13000 | K25: 10000 | L25: 9000 | M25: 3000 | N25: 6000 | O25: 1250 | P25: 6000 | Q25: 7000 | R25: 6000 | S25: 11000 | T25: 15000 | U25: 4500
A26: 2009 | B26: Yorks and Humber | C26: =SUM(D26:U26) -> 2219055 | D26: =SUM(D5:D25) -> 12880 | E26: =SUM(E5:E25) -> 24200 | F26: =SUM(F5:F25) -> 252750 | G26: =SUM(G5:G25) -> 99800 | H26: =SUM(H5:H25) -> 38000 | I26: =SUM(I5:I25) -> 102550 | J26: =SUM(J5:J25) -> 241750 | K26: =SUM(K5:K25) -> 103400 | ... U26: =SUM(U5:U25) -> 85850
A27: 2010 | B27: North Yorks County | C27: =SUM(D27:U27) -> 249500 | D27: 7000 | E27: 3500 | F27: 26000 | G27: 12000 | H27: 4000 | I27: 12000 | J27: 25000 | K27: 8000 | L27: 25000 | M27: 9000 | N27: 6000 | O27: 3000 | P27: 15000 | Q27: 13000 | R27: 12000 | S27: 22000 | T27: 34000 | U27: 13000
A28: 2010 | B28: South Yorks Met | C28: =SUM(D28:U28) -> 519250 | D28: 1250 | E28: 5000 | F28: 54000 | G28: 28000 | H28: 8000 | I28: 21000 | J28: 56000 | K28: 25000 | L28: 30000 | M28: 12000 | N28: 15000 | O28: 6000 | P28: 22000 | Q28: 41000 | R28: 33000 | S28: 55000 | T28: 84000 | U28: 23000
A29: 2010 | B29: West Yorks Met | C29: =SUM(D29:U29) -> 960750 | D29: 1750 | E29: 13000 | F29: 109000 | G29: 41000 | H29: 14000 | I29: 47000 | J29: 93000 | K29: 40000 | L29: 51000 | M29: 30000 | N29: 48000 | O29: 11000 | P29: 54000 | Q29: 83000 | R29: 56000 | S29: 96000 | T29: 133000 | U29: 40000
A30: 2010 | B30: Barnsley | C30: =SUM(D30:U30) -> 70900 | D30: 250 | E30: 400 | F30: 10000 | G30: 4000 | H30: 1000 | I30: 3000 | J30: 7000 | K30: 2500 | L30: 5000 | M30: 1250 | N30: 1500 | O30: 1000 | P30: 2500 | Q30: 4000 | R30: 5000 | S30: 7000 | T30: 13000 | U30: 2500
A31: 2010 | B31: Bradford | C31: =SUM(D31:U31) -> 193350 | D31: 350 | E31: 2500 | F31: 25000 | G31: 7000 | H31: 3000 | I31: 10000 | J31: 19000 | K31: 7000 | L31: 9000 | M31: 6000 | N31: 7000 | O31: 2500 | P31: 9000 | Q31: 13000 | R31: 11000 | S31: 22000 | T31: 32000 | U31: 8000
A32: 2010 | B32: Calderdale | C32: =SUM(D32:U32) -> 87550 | D32: 200 | E32: 450 | F32: 13000 | G32: 4000 | H32: 1250 | I32: 4500 | J32: 7000 | K32: 2500 | L32: 4500 | M32: 1750 | N32: 12000 | O32: 900 | P32: 2500 | Q32: 8000 | R32: 4000 | S32: 8000 | T32: 10000 | U32: 3000
A33: 2010 | B33: Craven | C33: =SUM(D33:U33) -> 26100 | D33: 600 | E33: 200 | F33: 2500 | G33: 1500 | H33: 350 | I33: 1250 | J33: 2500 | K33: 500 | L33: 2500 | M33: 300 | N33: 2000 | O33: 300 | P33: 2500 | Q33: 2500 | R33: 600 | S33: 2500 | T33: 2500 | U33: 1000
A34: 2010 | B34: Doncaster | C34: =SUM(D34:U34) -> 111050 | D34: 450 | E34: 1500 | F34: 9000 | G34: 7000 | H34: 2500 | I34: 4000 | J34: 14000 | K34: 9000 | L34: 6000 | M34: 1500 | N34: 2000 | O34: 600 | P34: 3500 | Q34: 8000 | R34: 7000 | S34: 11000 | T34: 19000 | U34: 5000
A35: 2010 | B35: ER Yorks | C35: =SUM(D35:U35) -> 117750 | D35: 3500 | E35: 1000 | F35: 14000 | G35: 6000 | H35: 2000 | I35: 4500 | J35: 12000 | K35: 5000 | L35: 8000 | M35: 2250 | N35: 1000 | O35: 1000 | P35: 4500 | Q35: 5000 | R35: 13000 | S35: 13000 | T35: 17000 | U35: 5000
A36: 2010 | B36: Hambleton | C36: =SUM(D36:U36) -> 39150 | D36: 1500 | E36: 400 | F36: 4000 | G36: 2000 | H36: 600 | I36: 2500 | J36: 3500 | K36: 1250 | L36: 3000 | M36: 600 | N36: 350 | O36: 450 | P36: 2000 | Q36: 1500 | R36: 5000 | S36: 3000 | T36: 6000 | U36: 1500
A37: 2010 | B37: Harrogate | C37: =SUM(D37:U37) -> 76250 | D37: 1500 | E37: 600 | F37: 4500 | G37: 2500 | H37: 1500 | I37: 4500 | J37: 8000 | K37: 2250 | L37: 7000 | M37: 7000 | N37: 2500 | O37: 900 | P37: 5000 | Q37: 3500 | R37: 2500 | S37: 7000 | T37: 11000 | U37: 4500
A38: 2010 | B38: Hull | C38: =SUM(D38:U38) -> 114935 | D38: 35 | E38: 1250 | F38: 18000 | G38: 6000 | H38: 1750 | I38: 5000 | J38: 13000 | K38: 4500 | L38: 6000 | M38: 2250 | N38: 1250 | O38: 900 | P38: 3500 | Q38: 12000 | R38: 7000 | S38: 12000 | T38: 16000 | U38: 4500
... A50: 2010 | B50: York | C50: =SUM(D50:U50) -> 102400 | D50: 250 | E50: 400 | F50: 4500 | G50: 4500 | H50: 1250 | I50: 2250 | J50: 13000 | K50: 9000 | L50: 9000 | M50: 2250 | N50: 5000 | O50: 1000 | P50: 6000 | Q50: 7000 | R50: 6000 | S50: 11000 | T50: 15000 | U50: 5000
A51: 2010 | B51: Yorks and Humber | C51: =SUM(D51:U51) -> 2204935 | D51: =SUM(D30:D50) -> 15010 | E51: =SUM(E30:E50) -> 26500 | F51: =SUM(F30:F50) -> 249000 | G51: =SUM(G30:G50) -> 106150 | H51: =SUM(H30:H50) -> 34700 | I51: =SUM(I30:I50) -> 98550 | J51: =SUM(J30:J50) -> 225750 | K51: =SUM(K30:K50) -> 103350 | ... U51: =SUM(U30:U50) -> 95750
A52: 2011 | B52: North Yorks County | C52: =SUM(D52:U52) -> 247000 | D52: 6000 | E52: 4000 | F52: 25000 | G52: 12000 | H52: 5000 | I52: 12000 | J52: 26000 | K52: 11000 | L52: 24000 | M52: 9000 | N52: 7000 | O52: 3000 | P52: 16000 | Q52: 12000 | R52: 11000 | S52: 22000 | T52: 31000 | U52: 11000
A53: 2011 | B53: South Yorks Met | C53: =SUM(D53:U53) -> 514000 | D53: 1000 | E53: 6000 | F53: 56000 | G53: 27000 | H53: 11000 | I53: 21000 | J53: 55000 | K53: 27000 | L53: 27000 | M53: 13000 | N53: 16000 | O53: 6000 | P53: 24000 | Q53: 37000 | R53: 30000 | S53: 57000 | T53: 80000 | U53: 20000
A54: 2011 | B54: West Yorks Met | C54: =SUM(D54:U54) -> 961750 | D54: 1750 | E54: 13000 | F54: 108000 | G54: 42000 | H54: 18000 | I54: 49000 | J54: 89000 | K54: 49000 | L54: 50000 | M54: 28000 | N54: 48000 | O54: 12000 | P54: 64000 | Q54: 83000 | R54: 51000 | S54: 95000 | T54: 124000 | U54: 37000
A55: 2011 | B55: Barnsley | C55: =SUM(D55:U55) -> 71125 | D55: 225 | E55: 500 | F55: 10000 | G55: 4500 | H55: 2000 | I55: 2500 | J55: 7000 | K55: 3500 | L55: 4500 | M55: 1000 | N55: 1500 | O55: 900 | P55: 3000 | Q55: 4000 | R55: 4000 | S55: 7000 | T55: 12000 | U55: 3000
A56: 2011 | B56: Bradford | C56: =SUM(D56:U56) -> 191750 | D56: 250 | E56: 2500 | F56: 24000 | G56: 7000 | H56: 3500 | I56: 10000 | J56: 19000 | K56: 8000 | L56: 8000 | M56: 6000 | N56: 7000 | O56: 2500 | P56: 11000 | Q56: 12000 | R56: 11000 | S56: 23000 | T56: 30000 | U56: 7000
A57: 2011 | B57: Calderdale | C57: =SUM(D57:U57) -> 87575 | D57: 175 | E57: 500 | F57: 13000 | G57: 4000 | H57: 1500 | I57: 4500 | J57: 7000 | K57: 3500 | L57: 5000 | M57: 2000 | N57: 10000 | O57: 900 | P57: 3500 | Q57: 8000 | R57: 4000 | S57: 8000 | T57: 9000 | U57: 3000
A58: 2011 | B58: Craven | C58: =SUM(D58:U58) -> 25825 | D58: 500 | E58: 125 | F58: 2500 | G58: 1250 | H58: 450 | I58: 1250 | J58: 2500 | K58: 700 | L58: 2500 | M58: 350 | N58: 2250 | O58: 300 | P58: 2250 | Q58: 2500 | R58: 500 | S58: 2500 | T58: 2500 | U58: 900
A59: 2011 | B59: Doncaster | C59: =SUM(D59:U59) -> 108700 | D59: 350 | E59: 1500 | F59: 10000 | G59: 7000 | H59: 3000 | I59: 4500 | J59: 13000 | K59: 8000 | L59: 6000 | M59: 1500 | N59: 2250 | O59: 600 | P59: 3500 | Q59: 8000 | R59: 6000 | S59: 10000 | T59: 19000 | U59: 4500
A60: 2011 | B60: ER Yorks | C60: =SUM(D60:U60) -> 113250 | D60: 3000 | E60: 1500 | F60: 14000 | G60: 6000 | H60: 2500 | I60: 4000 | J60: 12000 | K60: 7000 | L60: 8000 | M60: 2500 | N60: 1250 | O60: 1000 | P60: 5000 | Q60: 4500 | R60: 11000 | S60: 11000 | T60: 15000 | U60: 4000
A61: 2011 | B61: Hambleton | C61: =SUM(D61:U61) -> 37150 | D61: 1500 | E61: 700 | F61: 4000 | G61: 2000 | H61: 800 | I61: 2250 | J61: 3500 | K61: 1750 | L61: 2500 | M61: 500 | N61: 450 | O61: 450 | P61: 2500 | Q61: 1000 | R61: 4000 | S61: 2500 | T61: 5000 | U61: 1750
A62: 2011 | B62: Harrogate | C62: =SUM(D62:U62) -> 73750 | D62: 1250 | E62: 450 | F62: 4000 | G62: 2500 | H62: 1750 | I62: 4500 | J62: 8000 | K62: 3000 | L62: 7000 | M62: 7000 | N62: 3000 | O62: 800 | P62: 6000 | Q62: 2500 | R62: 2500 | S62: 6000 | T62: 10000 | U62: 3500
...

Sheet Sheet1
B1: Agriculture, forestry & fishing | C1: Mining, quarrying & utilities | D1: Manufacturing | E1: Construction | F1: Motor trades | G1: Wholesale | H1: Retail | I1: Transport & storage | J1: Accommodation & food services | K1: Information & communication | L1: Financial & insurance | M1: Property | N1: Professional, scientific & technical | O1: Business administration & support services | P1: Public administration & defence | Q1: Education | R1: Health | S1: Arts, entertainment, recreation & other services
A2: Barnsley | B2: =Data!D327/Data!$C327 -> 0.0023654642 | C2: =Data!E327/Data!$C327 -> 0.0070963927 | D2: =Data!F327/Data!$C327 -> 0.15375517 | E2: =Data!G327/Data!$C327 -> 0.059136606 | F2: =Data!H327/Data!$C327 -> 0.023654642 | G2: =Data!I327/Data!$C327 -> 0.035481963 | H2: =Data!J327/Data!$C327 -> 0.10644589 | I2: =Data!K327/Data!$C327 -> 0.082791248 | ... S2: =Data!U327/Data!$C327 -> 0.029568303
A3: Bradford | B3: =Data!D328/Data!$C328 -> 0.0014577259 | C3: =Data!E328/Data!$C328 -> 0.012147716 | D3: =Data!F328/Data!$C328 -> 0.11661808 | E3: =Data!G328/Data!$C328 -> 0.038872692 | F3: =Data!H328/Data!$C328 -> 0.021865889 | G3: =Data!I328/Data!$C328 -> 0.053449951 | H3: =Data!J328/Data!$C328 -> 0.1068999 | I3: =Data!K328/Data!$C328 -> 0.043731778 | ... S3: =Data!U328/Data!$C328 -> 0.029154519
A4: Calderdale | B4: =Data!D329/Data!$C329 -> 0.0019547612 | C4: =Data!E329/Data!$C329 -> 0.0067020385 | D4: =Data!F329/Data!$C329 -> 0.13404077 | E4: =Data!G329/Data!$C329 -> 0.050265289 | F4: =Data!H329/Data!$C329 -> 0.016755096 | G4: =Data!I329/Data!$C329 -> 0.055850321 | H4: =Data!J329/Data!$C329 -> 0.07819045 | I4: =Data!K329/Data!$C329 -> 0.033510193 | ... S4: =Data!U329/Data!$C329 -> 0.039095225
A5: Craven | B5: =Data!D330/Data!$C330 -> 0.019401778 | C5: =Data!E330/Data!$C330 -> 0.0056588521 | D5: =Data!F330/Data!$C330 -> 0.11317704 | E5: =Data!G330/Data!$C330 -> 0.048504446 | F5: =Data!H330/Data!$C330 -> 0.014551334 | G5: =Data!I330/Data!$C330 -> 0.040420372 | H5: =Data!J330/Data!$C330 -> 0.080840744 | I5: =Data!K330/Data!$C330 -> 0.025869038 | ... S5: =Data!U330/Data!$C330 -> 0.032336297
A6: Doncaster | B6: =Data!D331/Data!$C331 -> 0.0026246719 | C6: =Data!E331/Data!$C331 -> 0.01312336 | D6: =Data!F331/Data!$C331 -> 0.082489689 | E6: =Data!G331/Data!$C331 -> 0.059992501 | F6: =Data!H331/Data!$C331 -> 0.02999625 | G6: =Data!I331/Data!$C331 -> 0.033745782 | H6: =Data!J331/Data!$C331 -> 0.097487814 | I6: =Data!K331/Data!$C331 -> 0.13498313 | ... S6: =Data!U331/Data!$C331 -> 0.033745782
A7: ER Yorks | B7: =Data!D332/Data!$C332 -> 0.026871401 | C7: =Data!E332/Data!$C332 -> 0.019193858 | D7: =Data!F332/Data!$C332 -> 0.16122841 | E7: =Data!G332/Data!$C332 -> 0.046065259 | F7: =Data!H332/Data!$C332 -> 0.02303263 | G7: =Data!I332/Data!$C332 -> 0.038387716 | H7: =Data!J332/Data!$C332 -> 0.092130518 | I7: =Data!K332/Data!$C332 -> 0.046065259 | ... S7: =Data!U332/Data!$C332 -> 0.034548944
A8: Hambleton | B8: =Data!D333/Data!$C333 -> 0.030674847 | C8: =Data!E333/Data!$C333 -> 0.012269939 | D8: =Data!F333/Data!$C333 -> 0.14723926 | E8: =Data!G333/Data!$C333 -> 0.055214724 | F8: =Data!H333/Data!$C333 -> 0.019631902 | G8: =Data!I333/Data!$C333 -> 0.049079755 | H8: =Data!J333/Data!$C333 -> 0.098159509 | I8: =Data!K333/Data!$C333 -> 0.030674847 | ... S8: =Data!U333/Data!$C333 -> 0.036809816
A9: Harrogate | B9: =Data!D334/Data!$C334 -> 0.019455253 | C9: =Data!E334/Data!$C334 -> 0.0077821012 | D9: =Data!F334/Data!$C334 -> 0.064850843 | E9: =Data!G334/Data!$C334 -> 0.038910506 | F9: =Data!H334/Data!$C334 -> 0.019455253 | G9: =Data!I334/Data!$C334 -> 0.058365759 | H9: =Data!J334/Data!$C334 -> 0.10376135 | I9: =Data!K334/Data!$C334 -> 0.032425422 | ... S9: =Data!U334/Data!$C334 -> 0.038910506
A10: Hull | B10: =Data!D335/Data!$C335 -> 0.00015807777 | C10: =Data!E335/Data!$C335 -> 0.0098798609 | D10: =Data!F335/Data!$C335 -> 0.17388555 | E10: =Data!G335/Data!$C335 -> 0.055327221 | F10: =Data!H335/Data!$C335 -> 0.01778375 | G10: =Data!I335/Data!$C335 -> 0.039519444 | H10: =Data!J335/Data!$C335 -> 0.094846665 | I10: =Data!K335/Data!$C335 -> 0.039519444 | ... S10: =Data!U335/Data!$C335 -> 0.02766361
A11: Kirklees | B11: =Data!D336/Data!$C336 -> 0.0022033365 | C11: =Data!E336/Data!$C336 -> 0.0078690589 | D11: =Data!F336/Data!$C336 -> 0.16997167 | E11: =Data!G336/Data!$C336 -> 0.050361977 | F11: =Data!H336/Data!$C336 -> 0.025180988 | G11: =Data!I336/Data!$C336 -> 0.056657224 | H11: =Data!J336/Data!$C336 -> 0.10072395 | I11: =Data!K336/Data!$C336 -> 0.037771483 | ... S11: =Data!U336/Data!$C336 -> 0.037771483
A12: Leeds | B12: =Data!D337/Data!$C337 -> 0.00091752472 | C12: =Data!E337/Data!$C337 -> 0.012233663 | D12: =Data!F337/Data!$C337 -> 0.059129371 | E12: =Data!G337/Data!$C337 -> 0.036700989 | F12: =Data!H337/Data!$C337 -> 0.016311551 | G12: =Data!I337/Data!$C337 -> 0.034662045 | H12: =Data!J337/Data!$C337 -> 0.067285146 | I12: =Data!K337/Data!$C337 -> 0.040778877 | ... S12: =Data!U337/Data!$C337 -> 0.040778877
A13: NE Lincs | B13: =Data!D338/Data!$C338 -> 0.0014981273 | C13: =Data!E338/Data!$C338 -> 0.013483146 | D13: =Data!F338/Data!$C338 -> 0.16479401 | E13: =Data!G338/Data!$C338 -> 0.04494382 | F13: =Data!H338/Data!$C338 -> 0.029962547 | G13: =Data!I338/Data!$C338 -> 0.037453184 | H13: =Data!J338/Data!$C338 -> 0.10486891 | I13: =Data!K338/Data!$C338 -> 0.074906367 | ... S13: =Data!U338/Data!$C338 -> 0.033707865
... A22: York | B22: =Data!D347/Data!$C347 -> 0.0020515158 | C22: =Data!E347/Data!$C347 -> 0.0041030317 | D22: =Data!F347/Data!$C347 -> 0.036471393 | E22: =Data!G347/Data!$C347 -> 0.031912469 | F22: =Data!H347/Data!$C347 -> 0.013676772 | G22: =Data!I347/Data!$C347 -> 0.018235696 | H22: =Data!J347/Data!$C347 -> 0.10941418 | I22: =Data!K347/Data!$C347 -> 0.041030317 | ... S22: =Data!U347/Data!$C347 -> 0.041030317

Sheet Sheet2
A1: Table 2.4: Sample of dataset 2
A2: Year | B2: Area | C2: Agriculture, forestry & fishing | D2: Mining, quarrying & utilities | E2: Manufacturing | F2: Construction | G2: Motor trades | H2: Wholesale | I2: Retail | J2: Transport & storage | K2: Accommodation & food services | L2: Information & communication | M2: Financial & insurance | N2: Property | O2: Professional, scientific & technical | P2: Business administration & support services | Q2: Public administration & defence | R2: Education | S2: Health | T2: Arts, entertainment, recreation & other services
A3: 2009 | B3: Barnsley | C3: 225 | D3: 400 | E3: 11000 | F3: 4000 | G3: 1250 | H3: 2500 | I3: 7000 | J3: 2500 | K3: 4500 | L3: 1250 | M3: 1750 | N3: 1250 | O3: 3000 | P3: 3000 | Q3: 5000 | R3: 8000 | S3: 13000 | T3: 2500
A4: 2009 | B4: Bradford | C4: 300 | D4: 2250 | E4: 26000 | F4: 6000 | G4: 3000 | H4: 10000 | I4: 24000 | J4: 6000 | K4: 10000 | L4: 6000 | M4: 7000 | N4: 3000 | O4: 8000 | P4: 12000 | Q4: 12000 | R4: 23000 | S4: 29000 | T4: 7000
A5: 2009 | B5: Calderdale | C5: 175 | D5: 450 | E5: 14000 | F5: 3500 | G5: 1250 | H5: 5000 | I5: 7000 | J5: 3000 | K5: 5000 | L5: 2500 | M5: 8000 | N5: 1500 | O5: 3000 | P5: 5000 | Q5: 4000 | R5: 8000 | S5: 9000 | T5: 2500
A6: 2009 | B6: Craven | C6: 600 | D6: 200 | E6: 2250 | F6: 1500 | G6: 450 | H6: 1500 | I6: 3000 | J6: 700 | K6: 3000 | L6: 350 | M6: 3500 | N6: 500 | O6: 2000 | P6: 3000 | Q6: 300 | R6: 3000 | S6: 2500 | T6: 800
A7: 2009 | B7: Doncaster | C7: 350 | D7: 1500 | E7: 10000 | F7: 7000 | G7: 2500 | H7: 4500 | I7: 14000 | J7: 9000 | K7: 7000 | L7: 1500 | M7: 2000 | N7: 1000 | O7: 3500 | P7: 8000 | Q7: 6000 | R7: 11000 | S7: 19000 | T7: 4500
A8: 2009 | B8: ER Yorks | C8: 3000 | D8: 900 | E8: 14000 | F8: 5000 | G8: 2250 | H8: 5000 | I8: 12000 | J8: 5000 | K8: 9000 | L8: 2500 | M8: 2000 | N8: 1500 | O8: 5000 | P8: 5000 | Q8: 13000 | R8: 13000 | S8: 16000 | T8: 5000
A9: 2009 | B9: Hambleton | C9: 1250 | D9: 350 | E9: 4000 | F9: 1750 | G9: 700 | H9: 2500 | I9: 4000 | J9: 1250 | K9: 3000 | L9: 600 | M9: 400 | N9: 600 | O9: 2250 | P9: 1500 | Q9: 4500 | R9: 2500 | S9: 5000 | T9: 1750
A10: 2009 | B10: Harrogate | C10: 1250 | D10: 350 | E10: 4000 | F10: 2500 | G10: 1500 | H10: 4500 | I10: 8000 | J10: 2250 | K10: 7000 | L10: 7000 | M10: 3000 | N10: 1000 | O10: 5000 | P10: 3000 | Q10: 2250 | R10: 7000 | S10: 10000 | T10: 3500
A11: 2009 | B11: Hull | C11: 5 | D11: 1250 | E11: 17000 | F11: 5000 | G11: 2000 | H11: 6000 | I11: 14000 | J11: 5000 | K11: 6000 | L11: 2250 | M11: 1500 | N11: 1250 | O11: 4000 | P11: 11000 | Q11: 8000 | R11: 11000 | S11: 17000 | T11: 4000
A12: 2009 | B12: Kirklees | C12: 400 | D12: 1250 | E12: 26000 | F12: 6000 | G12: 3000 | H12: 8000 | I12: 17000 | J12: 6000 | K12: 8000 | L12: 5000 | M12: 2250 | N12: 2000 | O12: 6000 | P12: 10000 | Q12: 8000 | R12: 18000 | S12: 19000 | T12: 5000
A13: 2009 | B13: Leeds | C13: 600 | D13: 6000 | E13: 30000 | F13: 17000 | G13: 5000 | H13: 18000 | I13: 38000 | J13: 14000 | K13: 23000 | L13: 15000 | M13: 26000 | N13: 7000 | O13: 31000 | P13: 41000 | Q13: 23000 | R13: 37000 | S13: 48000 | T13: 17000
A14: 2009 | B14: NE Lincs | C14: 175 | D14: 500 | E14: 9000 | F14: 3000 | G14: 1750 | H14: 2500 | I14: 8000 | J14: 5000 | K14: 4000 | L14: 800 | M14: 1000 | N14: 1000 | O14: 2500 | P14: 4500 | Q14: 3000 | R14: 7000 | S14: 12000 | T14: 3000
... A23: 2009 | B23: York | C23: 225 | D23: 350 | E23: 4500 | F23: 4000 | G23: 1250 | H23: 2500 | I23: 13000 | J23: 10000 | K23: 9000 | L23: 3000 | M23: 6000 | N23: 1250 | O23: 6000 | P23: 7000 | Q23: 6000 | R23: 11000 | S23: 15000 | T23: 4500
